Workbook

Sheet Table7
A1: BL | B1: CC | C1: Year | D1: Scenario | E1: Month | F1: Key | G1: RateNo
A2: CT | B2: 412011 | C2: FY24 | D2: Actual | E2: Oct | F2: WCW | G2: 0.2056
A3: CT | B3: 412011 | C3: FY24 | D3: Actual | E3: Nov | F3: WCW | G3: 0.2056
A4: CT | B4: 412011 | C4: FY24 | D4: Actual | E4: Dec | F4: WCW | G4: 0.2056
A5: CT | B5: 412011 | C5: FY24 | D5: Actual | E5: Jan | F5: WCW | G5: 0.2056
A6: CT | B6: 412011 | C6: FY24 | D6: Actual | E6: Feb | F6: WCW | G6: 0.2056
A7: CT | B7: 412011 | C7: FY24 | D7: Actual | E7: Mar | F7: WCW | G7: 0.2056
A8: CT | B8: 412011 | C8: FY24 | D8: Actual | E8: Apr | F8: WCW | G8: 0.2056
A9: CT | B9: 412011 | C9: FY24 | D9: Actual | E9: May | F9: WCW | G9: 0.2056
A10: CT | B10: 412011 | C10: FY24 | D10: Actual | E10: Jun | F10: WCW | G10: 0.2056
A11: CT | B11: 412011 | C11: FY24 | D11: Actual | E11: Jul | F11: WCW | G11: 0.2056
A12: CT | B12: 412011 | C12: FY24 | D12: Actual | E12: Aug | F12: WCW | G12: 0.2056
A13: CT | B13: 412011 | C13: FY24 | D13: Actual | E13: Sep | F13: WCW | G13: 0.2056
... A36289: Key Supporting Function | B36289: 480057 | C36289: FY26 | D36289: Budget1 | E36289: Sep | F36289: Pooling | G36289: 0

Sheet CostDataBase
A1: Year | B1: Scenario | C1: Function | D1: Cost text | E1: Account | F1: Category | G1: Key | H1: Year Total | I1: Month | J1: Amount
A2: FY24 | B2: Actual | C2: HR | D2: HR | E2: 66860000 | F2: Functional cost | G2: headcount | H2: 9858298.1 | I2: Oct | J2: 0
A3: FY24 | B3: Actual | C3: HR | D3: HR | E3: 66860000 | F3: Functional cost | G3: headcount | H3: 9858298.1 | I3: Nov | J3: 1641555.7
A4: FY24 | B4: Actual | C4: HR | D4: HR | E4: 66860000 | F4: Functional cost | G4: headcount | H4: 9858298.1 | I4: Dec | J4: 820777.86
A5: FY24 | B5: Actual | C5: HR | D5: HR | E5: 66860000 | F5: Functional cost | G5: headcount | H5: 9858298.1 | I5: Jan | J5: 820777.86
A6: FY24 | B6: Actual | C6: HR | D6: HR | E6: 66860000 | F6: Functional cost | G6: headcount | H6: 9858298.1 | I6: Feb | J6: 820777.86
A7: FY24 | B7: Actual | C7: HR | D7: HR | E7: 66860000 | F7: Functional cost | G7: headcount | H7: 9858298.1 | I7: Mar | J7: 820777.86
A8: FY24 | B8: Actual | C8: HR | D8: HR | E8: 66860000 | F8: Functional cost | G8: headcount | H8: 9858298.1 | I8: Apr | J8: 820777.86
A9: FY24 | B9: Actual | C9: HR | D9: HR | E9: 66860000 | F9: Functional cost | G9: headcount | H9: 9858298.1 | I9: May | J9: 820777.86
A10: FY24 | B10: Actual | C10: HR | D10: HR | E10: 66860000 | F10: Functional cost | G10: headcount | H10: 9858298.1 | I10: Jun | J10: 820777.86
A11: FY24 | B11: Actual | C11: HR | D11: HR | E11: 66860000 | F11: Functional cost | G11: headcount | H11: 9858298.1 | I11: Jul | J11: 820777.86
A12: FY24 | B12: Actual | C12: HR | D12: HR | E12: 66860000 | F12: Functional cost | G12: headcount | H12: 9858298.1 | I12: Aug | J12: 820777.86
A13: FY24 | B13: Actual | C13: HR | D13: HR | E13: 66860000 | F13: Functional cost | G13: headcount | H13: 9858298.1 | I13: Sep | J13: 829741.67
... A229: FY24 | B229: Actual | C229: Procurement | D229: SOP SCM | E229: 61973300 | F229: Functional cost | G229: IM | H229: 0 | I229: Sep | J229: 0
A230: FY24 | B230: Actual | C230: Procurement Allocation | D230: Function P IM allocation to BL CC | F230: Functional cost | G230: IM | H230: -2196476.3 | I230: Oct | J230: -21307.49
A231: FY24 | B231: Actual | C231: Procurement Allocation | D231: Function P IM allocation to BL CC | F231: Functional cost | G231: IM | H231: -2196476.3 | I231: Nov | J231: -361449.2
A232: FY24 | B232: Actual | C232: Procurement Allocation | D232: Function P IM allocation to BL CC | F232: Functional cost | G232: IM | H232: -2196476.3 | I232: Dec | J232: -187399.27
A233: FY24 | B233: Actual | C233: Procurement Allocation | D233: Function P IM allocation to BL CC | F233: Functional cost | G233: IM | H233: -2196476.3 | I233: Jan | J233: -149157.35
A234: FY24 | B234: Actual | C234: Procurement Allocation | D234: Function P IM allocation to BL CC | F234: Functional cost | G234: IM | H234: -2196476.3 | I234: Feb | J234: -237840.34
A235: FY24 | B235: Actual | C235: Procurement Allocation | D235: Function P IM allocation to BL CC | F235: Functional cost | G235: IM | H235: -2196476.3 | I235: Mar | J235: -189868.63
A236: FY24 | B236: Actual | C236: Procurement Allocation | D236: Function P IM allocation to BL CC | F236: Functional cost | G236: IM | H236: -2196476.3 | I236: Apr | J236: -202429.97
A237: FY24 | B237: Actual | C237: Procurement Allocation | D237: Function P IM allocation to BL CC | F237: Functional cost | G237: IM | H237: -2196476.3 | I237: May | J237: -192988.93
A238: FY24 | B238: Actual | C238: Procurement Allocation | D238: Function P IM allocation to BL CC | F238: Functional cost | G238: IM | H238: -2196476.3 | I238: Jun | J238: -189063.37
A239: FY24 | B239: Actual | C239: Procurement Allocation | D239: Function P IM allocation to BL CC | F239: Functional cost | G239: IM | H239: -2196476.3 | I239: Jul | J239: -317631.46
A240: FY24 | B240: Actual | C240: Procurement Allocation | D240: Function P IM allocation to BL CC | F240: Functional cost | G240: IM | H240: -2196476.3 | I240: Aug | J240: -60313.37
A241: FY24 | B241: Actual | C241: Procurement Allocation | D241: Function P IM allocation to BL CC | F241: Functional cost | G241: IM | H241: -2196476.3 | I241: Sep | J241: -87026.96
A242: FY24 | B242: Actual | C242: Procurement | D242: Pooling & MPC | E242: 66860000 | F242: Functional cost | G242: Pooling | H242: 1743794.4 | I242: Oct | J242: 0
A243: FY24 | B243: Actual | C243: Procurement | D243: Pooling & MPC | E243: 66860000 | F243: Functional cost | G243: Pooling | H243: 1743794.4 | I243: Nov | J243: 305164.02
A244: FY24 | B244: Actual | C244: Procurement | D244: Pooling & MPC | E244: 66860000 | F244: Functional cost | G244: Pooling | H244: 1743794.4 | I244: Dec | J244: 152582.01
A245: FY24 | B245: Actual | C245: Procurement | D245: Pooling & MPC | E245: 66860000 | F245: Functional cost | G245: Pooling | H245: 1743794.4 | I245: Jan | J245: 152582.01
A246: FY24 | B246: Actual | C246: Procurement | D246: Pooling & MPC | E246: 66860000 | F246: Functional cost | G246: Pooling | H246: 1743794.4 | I246: Feb | J246: 152582.01
A247: FY24 | B247: Actual | C247: Procurement | D247: Pooling & MPC | E247: 66860000 | F247: Functional cost | G247: Pooling | H247: 1743794.4 | I247: Mar | J247: 152582.01
A248: FY24 | B248: Actual | C248: Procurement | D248: Pooling & MPC | E248: 66860000 | F248: Functional cost | G248: Pooling | H248: 1743794.4 | I248: Apr | J248: 152582.01
A249: FY24 | B249: Actual | C249: Procurement | D249: Pooling & MPC | E249: 66860000 | F249: Functional cost | G249: Pooling | H249: 1743794.4 | I249: May | J249: 152582.01
A250: FY24 | B250: Actual | C250: Procurement | D250: Pooling & MPC | E250: 66860000 | F250: Functional cost | G250: Pooling | H250: 1743794.4 | I250: Jun | J250: 152582.01
A251: FY24 | B251: Actual | C251: Procurement | D251: Pooling & MPC | E251: 66860000 | F251: Functional cost | G251: Pooling | H251: 1743794.4 | I251: Jul | J251: 152582.01
A252: FY24 | B252: Actual | C252: Procurement | D252: Pooling & MPC | E252: 66860000 | F252: Functional cost | G252: Pooling | H252: 1743794.4 | I252: Aug | J252: 145316.2
A253: FY24 | B253: Actual | C253: Procurement | D253: Pooling & MPC | E253: 66860000 | F253: Functional cost | G253: Pooling | H253: 1743794.4 | I253: Sep | J253: 72658.1
A254: FY24 | B254: Actual | C254: Procurement Allocation | D254: Function P Pooling allocation to BL CC | F254: Functional cost | G254: Pooling | H254: -1743794.4 | I254: Oct | J254: 0
A255: FY24 | B255: Actual | C255: Procurement Allocation | D255: Function P Pooling allocation to BL CC | F255: Functional cost | G255: Pooling | H255: -1743794.4 | I255: Nov | J255: -305164.02
...

Sheet Cost
A3: Year | B3: Scenario | C3: Function | D3: Cost text | E3: Account | F3: Category | G3: Key | H3: Oct | I3: Nov | J3: Dec | K3: Jan | L3: Feb | M3: Mar | N3: Apr | O3: May | P3: Jun | Q3: Jul | R3: Aug | S3: Sep | T3: Year Total
A4: FY24 | B4: Actual | C4: =VLOOKUP(D4,'Cost text mapping'!B:C,2,0) -> HR | D4: HR | E4: 66860000 | F4: Functional cost | G4: headcount | H4: 0 | I4: 1641555.7 | J4: 820777.86 | K4: 820777.86 | L4: 820777.86 | M4: 820777.86 | N4: 820777.86 | O4: 820777.86 | P4: 820777.86 | Q4: 820777.86 | R4: 820777.86 | S4: 829741.67 | T4: =SUM(H4:S4) -> 9858298.1
A5: FY24 | B5: Actual | C5: =VLOOKUP(D5,'Cost text mapping'!B:C,2,0) -> HR | D5: GBS H2R | E5: 61760040 | F5: Functional cost | G5: headcount | H5: 0 | I5: 0 | J5: 421598.65 | K5: 132704.53 | L5: 139196.42 | M5: 135499.06 | N5: 133992.88 | O5: 126488.19 | P5: 125372.5 | Q5: 124704.03 | R5: 124704.03 | S5: 122383.32 | T5: =SUM(H5:S5) -> 1586643.6
A6: FY24 | B6: Actual | C6: =VLOOKUP(D6,'Cost text mapping'!B:C,2,0) -> HR | D6: Field HR | E6: 61974200 | F6: Functional cost | G6: headcount | H6: 0 | I6: 0 | J6: 0 | K6: 58049.65 | L6: 14512.413 | M6: 14512.413 | N6: 14512.413 | O6: 14512.413 | P6: 34676.43 | Q6: 14512.41 | R6: 14512.41 | S6: 14512.4 | T6: =SUM(H6:S6) -> 194312.95
A7: FY24 | B7: Actual | C7: =VLOOKUP(D7,'Cost text mapping'!B:C,2,0) -> HR Allocation | D7: Function HR allocation to BL CC | E7: 91800150 | F7: Functional cost | G7: 480055 Cycle | H7: -974916.67 | I7: -974916.67 | J7: -974916.67 | K7: -974916.67 | L7: -974916.67 | M7: -974916.67 | N7: -974916.67 | O7: -974916.67 | P7: -974916.67 | Q7: -974916.67 | R7: -974916.67 | S7: -974916.67 | T7: =SUM(H7:S7) -> -11699000
A8: FY24 | B8: Actual | C8: =VLOOKUP(D8,'Cost text mapping'!B:C,2,0) -> IT | D8: 7092 GS IT_SW | E8: 66860000 | F8: Functional cost | G8: SAM | H8: 0 | I8: 0 | J8: 2319576.2 | K8: 763916.6 | L8: 1529909.6 | M8: 0 | N8: 755542.26 | O8: 1182550.4 | P8: 769885.52 | Q8: 856110.23 | R8: 775650.48 | S8: 766815.79 | T8: =SUM(H8:S8) -> 9719957.1
A9: FY24 | B9: Actual | C9: =VLOOKUP(D9,'Cost text mapping'!B:C,2,0) -> IT | D9: 7092 GS IT_End user | E9: 66860000 | F9: Functional cost | G9: WCW | H9: 0 | I9: 0 | J9: 737408.07 | K9: 242853.96 | L9: 390782.15 | M9: -115331.14 | N9: 205533.94 | O9: 208081.15 | P9: 207324.45 | Q9: 188505.77 | R9: 211004.08 | S9: 208600.74 | T9: =SUM(H9:S9) -> 2484763.2
A10: FY24 | B10: Actual | C10: =VLOOKUP(D10,'Cost text mapping'!B:C,2,0) -> IT | D10: 5547 GS IT | E10: 61973210 | F10: Functional cost | G10: WCW | H10: 0 | I10: 85760.08 | J10: 271881.91 | K10: 42226.03 | L10: 91355.67 | M10: 86610.64 | N10: 86563.82 | O10: 70321.42 | P10: 107494.71 | Q10: 71102.48 | R10: 90114.79 | S10: 70960.48 | T10: =SUM(H10:S10) -> 1074392
A11: FY24 | B11: Actual | C11: =VLOOKUP(D11,'Cost text mapping'!B:C,2,0) -> IT | D11: 5547 DLP | E11: 61639010 | F11: Functional cost | G11: WCW | H11: 0 | I11: 64481.6 | J11: 0 | K11: 65080.8 | L11: 51898 | M11: 140486.7 | N11: 64634.45 | O11: 64374.75 | P11: 61414.85 | Q11: 57177.6 | R11: 55805.4 | S11: 60912.4 | T11: =SUM(H11:S11) -> 686266.55
A12: FY24 | B12: Actual | C12: =VLOOKUP(D12,'Cost text mapping'!B:C,2,0) -> IT | D12: P41 | E12: 66860000 | F12: Functional cost | G12: WCW | H12: 0 | I12: 0 | J12: 0 | K12: 0 | L12: 1560461.4 | M12: 0 | N12: 0 | O12: 780180.76 | P12: 0 | Q12: 784406.6 | R12: 0 | S12: 0 | T12: =SUM(H12:S12) -> 3125048.8
A13: FY24 | B13: Actual | C13: =VLOOKUP(D13,'Cost text mapping'!B:C,2,0) -> IT | D13: M365 Collaboration | E13: 66860000 | F13: Functional cost | G13: WCW | H13: 0 | I13: 0 | J13: 0 | K13: 0 | L13: 0 | M13: 105573.16 | N13: 15561.567 | O13: 0 | P13: 22477.479 | Q13: 0 | R13: 0 | S13: 0 | T13: =SUM(H13:S13) -> 143612.21
A14: FY24 | B14: Actual | C14: =VLOOKUP(D14,'Cost text mapping'!B:C,2,0) -> IT | D14: M365 Messaging | E14: 66860000 | F14: Functional cost | G14: WCW | H14: 0 | I14: 0 | J14: 0 | K14: 0 | L14: 0 | M14: 27604.36 | N14: 26880.322 | O14: 0 | P14: 8606.8675 | Q14: 0 | R14: 0 | S14: 0 | T14: =SUM(H14:S14) -> 63091.55
A15: FY24 | B15: Actual | C15: =VLOOKUP(D15,'Cost text mapping'!B:C,2,0) -> IT | D15: MWP | E15: 61639010 | F15: Functional cost | G15: WCW | H15: 0 | I15: 0 | J15: 0 | K15: 0 | L15: 0 | M15: 477544.45 | N15: 203849.21 | O15: 207053.42 | P15: 137191.95 | Q15: 221390.78 | R15: 178031.77 | S15: 483203.83 | T15: =SUM(H15:S15) -> 1908265.4
... A22: FY24 | B22: Actual | C22: =VLOOKUP(D22,'Cost text mapping'!B:C,2,0) -> Procurement | D22: SOP SCM | E22: 61973300 | F22: Functional cost | G22: IM | H22: 0 | I22: 0 | J22: 0 | K22: 0 | L22: 0 | M22: 0 | N22: 0 | O22: 0 | P22: 0 | Q22: 0 | R22: 0 | S22: 0 | T22: =SUM(H22:S22) -> 0
A23: FY24 | B23: Actual | C23: =VLOOKUP(D23,'Cost text mapping'!B:C,2,0) -> Procurement Allocation | D23: Function P IM allocation to BL CC | F23: Functional cost | G23: IM | H23: =-SUM(H20:H22) -> -21307.49 | I23: =-SUM(I20:I22) -> -361449.2 | J23: =-SUM(J20:J22) -> -187399.27 | K23: =-SUM(K20:K22) -> -149157.35 | L23: =-SUM(L20:L22) -> -237840.34 | M23: =-SUM(M20:M22) -> -189868.63 | N23: =-SUM(N20:N22) -> -202429.97 | O23: =-SUM(O20:O22) -> -192988.93 | ... S23: =-SUM(S20:S22) -> -87026.96 | T23: =SUM(H23:S23) -> -2196476.3
A24: FY24 | B24: Actual | C24: =VLOOKUP(D24,'Cost text mapping'!B:C,2,0) -> Procurement | D24: Pooling & MPC | E24: 66860000 | F24: Functional cost | G24: Pooling | H24: 0 | I24: 305164.02 | J24: 152582.01 | K24: 152582.01 | L24: 152582.01 | M24: 152582.01 | N24: 152582.01 | O24: 152582.01 | P24: 152582.01 | Q24: 152582.01 | R24: 145316.2 | S24: 72658.1 | T24: =SUM(H24:S24) -> 1743794.4
A25: FY24 | B25: Actual | C25: =VLOOKUP(D25,'Cost text mapping'!B:C,2,0) -> Procurement Allocation | D25: Function P Pooling allocation to BL CC | F25: Functional cost | G25: Pooling | H25: =-H24 -> 0 | I25: =-I24 -> -305164.02 | J25: =-J24 -> -152582.01 | K25: =-K24 -> -152582.01 | L25: =-L24 -> -152582.01 | M25: =-M24 -> -152582.01 | N25: =-N24 -> -152582.01 | O25: =-O24 -> -152582.01 | ... S25: =-S24 -> -72658.1 | T25: =SUM(H25:S25) -> -1743794.4
A26: FY25 | B26: Actual | C26: =VLOOKUP(D26,'Cost text mapping'!B:C,2,0) -> HR | D26: HR | E26: 66860000 | F26: Functional cost | G26: headcount | H26: 0 | I26: 1633705 | J26: 816852.5 | K26: 816852.5 | L26: 816852.5 | M26: 816852.5 | N26: 816852.5 | O26: 816852.5 | P26: 816852.5 | Q26: 816852.5 | R26: 816852.5 | S26: 816852.5 | T26: =SUM(H26:S26) -> 9802230
A27: FY25 | B27: Actual | C27: =VLOOKUP(D27,'Cost text mapping'!B:C,2,0) -> HR | D27: GBS H2R | E27: 61760040 | F27: Functional cost | G27: headcount | H27: 82739.2 | I27: 161264.28 | J27: 114511.99 | K27: 112380 | L27: 112956.99 | M27: 111858.8 | N27: 113134.89 | O27: 113994.52 | P27: 111318.21 | Q27: 113651.82 | R27: 114896.97 | S27: 107111.08 | T27: =SUM(H27:S27) -> 1369818.8
A28: FY25 | B28: Actual | C28: =VLOOKUP(D28,'Cost text mapping'!B:C,2,0) -> HR | D28: Field HR | E28: 61974200 | F28: Functional cost | G28: headcount | H28: 0 | I28: 0 | J28: 0 | K28: 62196.68 | L28: 0 | M28: 15549.17 | N28: 15549.17 | O28: 31098.34 | P28: 36222.13 | Q28: -23.41 | R28: 15549 | S28: 53913.96 | T28: =SUM(H28:S28) -> 230055.04
A29: FY25 | B29: Actual | C29: =VLOOKUP(D29,'Cost text mapping'!B:C,2,0) -> HR Allocation | D29: Function HR allocation to BL CC | E29: 91800150 | F29: Functional cost | G29: 480055 Cycle | H29: -968000 | I29: -968000 | J29: -968000 | K29: -968000 | L29: -968000 | M29: -968000 | N29: -968000 | O29: -968000 | P29: -968000 | Q29: -968000 | R29: -968000 | S29: -968000 | T29: =SUM(H29:S29) -> -11616000
A30: FY25 | B30: Actual | C30: =VLOOKUP(D30,'Cost text mapping'!B:C,2,0) -> IT | D30: 7092 GS IT_SW | E30: 66860000 | F30: Functional cost | G30: SAM | H30: 0 | I30: 1887302.7 | J30: 803441.88 | K30: 1348772.8 | L30: 942069.28 | M30: 971140.07 | N30: 438401.57 | O30: 1010988.8 | P30: 1028478.3 | Q30: -292109.39 | R30: 1032643.6 | S30: 1039379.8 | T30: =SUM(H30:S30) -> 10210509
A31: FY25 | B31: Actual | C31: =VLOOKUP(D31,'Cost text mapping'!B:C,2,0) -> IT | D31: 7092 GS IT_End user | E31: 66860000 | F31: Functional cost | G31: WCW | H31: 0 | I31: 244688.5 | J31: 103798.25 | K31: 103840.69 | L31: 168334.15 | M31: 174628.68 | N31: 182809.06 | O31: 180649.08 | P31: 183774.2 | Q31: 157090.31 | R31: 184518.47 | S31: 185722.15 | T31: =SUM(H31:S31) -> 1869853.5
A32: FY25 | B32: Actual | C32: =VLOOKUP(D32,'Cost text mapping'!B:C,2,0) -> IT | D32: 5547 GS IT | E32: 61973210 | F32: Functional cost | G32: WCW | H32: 0 | I32: 0 | J32: 57507.02 | K32: 21741.2 | L32: 21878.2 | M32: 38803.8 | N32: 23230 | O32: 22781.8 | P32: 23270.4 | Q32: 23374.6 | R32: 23460.8 | S32: 23327.4 | T32: =SUM(H32:S32) -> 279375.22
A33: FY25 | B33: Actual | C33: =VLOOKUP(D33,'Cost text mapping'!B:C,2,0) -> IT | D33: P41 | E33: 66860000 | F33: Functional cost | G33: WCW | H33: 0 | I33: 0 | J33: 819416.38 | K33: 0 | L33: 0 | M33: 694383 | N33: 0 | O33: 0 | P33: 824247.4 | Q33: 0 | R33: 820398.12 | S33: 0 | T33: =SUM(H33:S33) -> 3158444.9
A34: FY25 | B34: Actual | C34: =VLOOKUP(D34,'Cost text mapping'!B:C,2,0) -> IT | D34: M365 Collaboration | E34: 66860000 | F34: Functional cost | G34: WCW | H34: 0 | I34: 16707.694 | J34: 21038.076 | K34: 23683.68 | L34: 19581.327 | M34: 22575.408 | N34: 0 | O34: 0 | P34: 0 | Q34: 0 | R34: 0 | S34: 0 | T34: =SUM(H34:S34) -> 103586.19
A35: FY25 | B35: Actual | C35: =VLOOKUP(D35,'Cost text mapping'!B:C,2,0) -> IT | D35: M365 Messaging | E35: 66860000 | F35: Functional cost | G35: WCW | H35: 0 | I35: 9204.6958 | J35: 3978.8336 | K35: 7768.8323 | L35: -5748.9513 | M35: 13155.869 | N35: 0 | O35: 0 | P35: 0 | Q35: 0 | R35: 0 | S35: 0 | T35: =SUM(H35:S35) -> 28359.279
A36: FY25 | B36: Actual | C36: =VLOOKUP(D36,'Cost text mapping'!B:C,2,0) -> IT | D36: MWP | E36: 66860000 | F36: Functional cost | G36: WCW | H36: 0 | I36: 78643.866 | J36: 221297.08 | K36: 159471.62 | L36: 138963.12 | M36: 213276.97 | N36: 321525.1 | O36: 353273.91 | P36: 348192.49 | Q36: 396891.43 | R36: 483438.02 | S36: 744306.76 | T36: =SUM(H36:S36) -> 3459280.4
A37: FY25 | B37: Actual | C37: =VLOOKUP(D37,'Cost text mapping'!B:C,2,0) -> IT | D37: SD-LAN Local | E37: 61639010 | F37: Functional cost | G37: WCW | H37: 0 | I37: 0 | J37: 563588.38 | K37: 187862.79 | L37: 195152.54 | M37: 173973.46 | N37: 173973.46 | O37: 173973.46 | P37: 173973.46 | Q37: 484134.61 | R37: 488587.3 | S37: 68126.91 | T37: =SUM(H37:S37) -> 2683346.4
... A44: FY25 | B44: Actual | C44: =VLOOKUP(D44,'Cost text mapping'!B:C,2,0) -> Procurement | D44: SOP SCM | E44: 61973300 | F44: Functional cost | G44: IM | H44: 0 | I44: 0 | J44: 0 | K44: 0 | L44: 0 | M44: 0 | N44: 0 | O44: 0 | P44: 0 | Q44: 0 | R44: 0 | S44: 0 | T44: =SUM(H44:S44) -> 0
A45: FY25 | B45: Actual | C45: =VLOOKUP(D45,'Cost text mapping'!B:C,2,0) -> Procurement Allocation | D45: Function P IM allocation to BL CC | F45: Functional cost | G45: IM | H45: =-SUM(H42:H44) -> -36608.37 | I45: =-SUM(I42:I44) -> -382291.38 | J45: =-SUM(J42:J44) -> -202562.76 | K45: =-SUM(K42:K44) -> -205376.34 | L45: =-SUM(L42:L44) -> -191014.37 | M45: =-SUM(M42:M44) -> -202007.58 | N45: =-SUM(N42:N44) -> -201303.35 | O45: =-SUM(O42:O44) -> -201900.34 | ... S45: =-SUM(S42:S44) -> -202910.77 | T45: =SUM(H45:S45) -> -2434929.2
A46: FY25 | B46: Actual | C46: =VLOOKUP(D46,'Cost text mapping'!B:C,2,0) -> Procurement | D46: Pooling & MPC | E46: 66860000 | F46: Functional cost | G46: Pooling | H46: 0 | I46: 320422.16 | J46: 160211.08 | K46: 160211.08 | L46: 160211.08 | M46: 160211.08 | N46: 160211.08 | O46: 160211.08 | P46: 160211.08 | Q46: 160211.08 | R46: 160211.08 | S46: 160211.08 | T46: =SUM(H46:S46) -> 1922533
A47: FY25 | B47: Actual | C47: =VLOOKUP(D47,'Cost text mapping'!B:C,2,0) -> Procurement Allocation | D47: Function P Pooling allocation to BL CC | F47: Functional cost | G47: Pooling | H47: =-H46 -> 0 | I47: =-I46 -> -320422.16 | J47: =-J46 -> -160211.08 | K47: =-K46 -> -160211.08 | L47: =-L46 -> -160211.08 | M47: =-M46 -> -160211.08 | N47: =-N46 -> -160211.08 | O47: =-O46 -> -160211.08 | ... S47: =-S46 -> -160211.08 | T47: =SUM(H47:S47) -> -1922533
A48: FY26 | B48: Budget1 | C48: =VLOOKUP(D48,'Cost text mapping'!B:C,2,0) -> HR | D48: HR | E48: 66860000 | F48: Functional cost | G48: headcount | H48: 865250 | I48: 865250 | J48: 865250 | K48: 865250 | L48: 865250 | M48: 865250 | N48: 865250 | O48: 865250 | P48: 865250 | Q48: 865250 | R48: 865250 | S48: 865250 | T48: =SUM(H48:S48) -> 10383000
A49: FY26 | B49: Budget1 | C49: =VLOOKUP(D49,'Cost text mapping'!B:C,2,0) -> HR | D49: GBS H2R | E49: 61760040 | F49: Functional cost | G49: headcount | H49: 122603.33 | I49: 122603.33 | J49: 122603.33 | K49: 122603.33 | L49: 122603.33 | M49: 122603.33 | N49: 122603.33 | O49: 122603.33 | P49: 122603.33 | Q49: 122603.33 | R49: 122603.33 | S49: 122603.33 | T49: =SUM(H49:S49) -> 1471240
A50: FY26 | B50: Budget1 | C50: =VLOOKUP(D50,'Cost text mapping'!B:C,2,0) -> HR | D50: Field HR | E50: 61974200 | F50: Functional cost | G50: headcount | H50: 16678.583 | I50: 16678.583 | J50: 16678.583 | K50: 16678.583 | L50: 16678.583 | M50: 16678.583 | N50: 16678.583 | O50: 16678.583 | P50: 16678.583 | Q50: 16678.583 | R50: 16678.583 | S50: 16678.583 | T50: =SUM(H50:S50) -> 200143
A51: FY26 | B51: Budget1 | C51: =VLOOKUP(D51,'Cost text mapping'!B:C,2,0) -> HR Allocation | D51: Function HR allocation to BL CC | E51: 91800150 | F51: Functional cost | G51: 480055 Cycle | H51: -1004531.9 | I51: -1004531.9 | J51: -1004531.9 | K51: -1004531.9 | L51: -1004531.9 | M51: -1004531.9 | N51: -1004531.9 | O51: -1004531.9 | P51: -1004531.9 | Q51: -1004531.9 | R51: -1004531.9 | S51: -1004531.9 | T51: =SUM(H51:S51) -> -12054383
A52: FY26 | B52: Budget1 | C52: =VLOOKUP(D52,'Cost text mapping'!B:C,2,0) -> IT | D52: 7092 GS IT_SW | E52: 66860000 | F52: Functional cost | G52: SAM | H52: 977413 | I52: 977413 | J52: 977413 | K52: 977413 | L52: 977413 | M52: 977413 | N52: 977413 | O52: 977413 | P52: 977413 | Q52: 977413 | R52: 977413 | S52: 1787413 | T52: =SUM(H52:S52) -> 12538956
A53: FY26 | B53: Budget1 | C53: =VLOOKUP(D53,'Cost text mapping'!B:C,2,0) -> IT | D53: 7092 GS IT_End user | E53: 66860000 | F53: Functional cost | G53: WCW | H53: 161138 | I53: 161138 | J53: 161138 | K53: 161138 | L53: 161138 | M53: 161138 | N53: 161138 | O53: 161138 | P53: 161138 | Q53: 161138 | R53: 161138 | S53: 161138 | T53: =SUM(H53:S53) -> 1933656
A54: FY26 | B54: Budget1 | C54: =VLOOKUP(D54,'Cost text mapping'!B:C,2,0) -> IT | D54: 5547 GS IT | E54: 61973210 | F54: Functional cost | G54: WCW | H54: 27921 | I54: 27921 | J54: 27921 | K54: 27921 | L54: 27921 | M54: 27921 | N54: 27921 | O54: 27921 | P54: 27921 | Q54: 27921 | R54: 27921 | S54: 25574 | T54: =SUM(H54:S54) -> 332705
...

Sheet Rate
B1: Year | C1: FY24 | D1: FY24 | E1: FY24 | F1: FY24 | G1: FY24 | H1: FY24 | I1: FY24 | J1: FY24 | K1: FY24 | L1: FY24 | M1: FY24 | N1: FY24 | O1: FY24 | P1: FY24 | Q1: FY24 | R1: FY24 | S1: FY24 | T1: FY24 | U1: FY24 | V1: FY24 | W1: FY24 | X1: FY24 | Y1: FY24 | Z1: FY24 | AA1: FY24 | AB1: FY24 | AC1: FY24 | AD1: FY24 | AE1: FY24 | AF1: FY24 | AG1: FY24 | AH1: FY24 | AI1: FY24 | AJ1: FY24 | AK1: FY24 | AL1: FY24 | AM1: FY24 | AN1: FY24 | AO1: FY24 | AP1: FY24 | AQ1: FY24 | AR1: FY24 | AS1: FY24 | AT1: FY24 | AU1: FY24 | AV1: FY24 | AW1: FY24 | AX1: FY24 | AY1: FY24 | AZ1: FY24 | BA1: FY24 | BB1: FY24 | BC1: FY24 | BD1: FY24 | BE1: FY24 | BF1: FY24 | BG1: FY24 | BH1: FY24 | BI1: FY24 | BJ1: FY24 | BK1: FY24 | BL1: FY24 | BM1: FY24 | BN1: FY24 | BO1: FY24 | BP1: FY24 | BQ1: FY24 | BR1: FY24 | BS1: FY24 | BT1: FY24 | BU1: FY24 | BV1: FY24 | BW1: FY24 | BX1: FY24 | BY1: FY24 | BZ1: FY24 | CA1: FY24 | CB1: FY24 | CC1: FY24 | CD1: FY24 | CE1: FY24 | CF1: FY24 | CG1: FY24 | CH1: FY24 | CI1: FY24 | CJ1: FY24 | CK1: FY24 | CL1: FY24 | CM1: FY24 | CN1: FY24 | CO1: FY24 | CP1: FY24 | CQ1: FY24 | CR1: FY24 | CS1: FY24 | CT1: FY24 | CU1: FY25 | CV1: FY25 | CW1: FY25 | CX1: FY25 | CY1: FY25 | CZ1: FY25 | DA1: FY25 | DB1: FY25 | DC1: FY25 | DD1: FY25 | DE1: FY25 | DF1: FY25 | DG1: FY25 | DH1: FY25 | DI1: FY25 | DJ1: FY25 | DK1: FY25 | DL1: FY25 | DM1: FY25 | DN1: FY25 | DO1: FY25 | DP1: FY25 | DQ1: FY25 | DR1: FY25 | DS1: FY25 | DT1: FY25 | DU1: FY25 | DV1: FY25 | DW1: FY25 | DX1: FY25 | DY1: FY25 | DZ1: FY25 | EA1: FY25 | EB1: FY25 | EC1: FY25 | ED1: FY25 | EE1: FY25 | EF1: FY25 | EG1: FY25 | EH1: FY25 | EI1: FY25 | EJ1: FY25 | EK1: FY25 | EL1: FY25 | EM1: FY25 | EN1: FY25 | EO1: FY25 | EP1: FY25 | EQ1: FY25 | ER1: FY25 | ES1: FY25 | ET1: FY25 | EU1: FY25 | EV1: FY25 | EW1: FY25 | EX1: FY25 | EY1: FY25 | EZ1: FY25 | FA1: FY25 | FB1: FY25 | FC1: FY25 | FD1: FY25 | FE1: FY25 | FF1: FY25 | FG1: FY25 | FH1: FY25 | FI1: FY25 | FJ1: FY25 | FK1: FY25 | FL1: FY25 | FM1: FY25 | FN1: FY25 | FO1: FY25 | FP1: FY25 | FQ1: FY25 | FR1: FY25 | FS1: FY25 | FT1: FY25 | FU1: FY25 | FV1: FY25 | FW1: FY25 | FX1: FY25 | FY1: FY25 | FZ1: FY25 | GA1: FY25 | GB1: FY25 | GC1: FY25 | GD1: FY25 | GE1: FY25 | GF1: FY25 | GG1: FY25 | GH1: FY25 | GI1: FY25 | GJ1: FY25 | GK1: FY25 | GL1: FY25 | GM1: FY26 | GN1: FY26 | GO1: FY26 | GP1: FY26 | GQ1: FY26 | GR1: FY26 | GS1: FY26 | GT1: FY26 | GU1: FY26 | GV1: FY26 | GW1: FY26 | GX1: FY26 | GY1: FY26 | GZ1: FY26 | HA1: FY26 | HB1: FY26 | HC1: FY26 | HD1: FY26 | HE1: FY26 | HF1: FY26 | HG1: FY26 | HH1: FY26 | HI1: FY26 | HJ1: FY26 | HK1: FY26 | HL1: FY26 | HM1: FY26 | HN1: FY26 | HO1: FY26 | HP1: FY26 | HQ1: FY26 | HR1: FY26 | HS1: FY26 | HT1: FY26 | HU1: FY26 | HV1: FY26 | HW1: FY26 | HX1: FY26 | HY1: FY26 | HZ1: FY26 | IA1: FY26 | IB1: FY26 | IC1: FY26 | ID1: FY26 | IE1: FY26 | IF1: FY26 | IG1: FY26 | IH1: FY26 | II1: FY26 | IJ1: FY26 | IK1: FY26 | IL1: FY26 | IM1: FY26 | IN1: FY26 | IO1: FY26 | IP1: FY26 | IQ1: FY26 | IR1: FY26 | IS1: FY26 | IT1: FY26 | IU1: FY26 | IV1: FY26 | IW1: FY26 | IX1: FY26 | IY1: FY26 | IZ1: FY26 | JA1: FY26 | JB1: FY26 | JC1: FY26 | JD1: FY26 | JE1: FY26 | JF1: FY26 | JG1: FY26 | JH1: FY26 | JI1: FY26 | JJ1: FY26 | JK1: FY26 | JL1: FY26 | JM1: FY26 | JN1: FY26 | JO1: FY26 | JP1: FY26 | JQ1: FY26 | JR1: FY26 | JS1: FY26 | JT1: FY26 | JU1: FY26 | JV1: FY26 | JW1: FY26 | JX1: FY26 | JY1: FY26 | JZ1: FY26 | KA1: FY26 | KB1: FY26 | KC1: FY26 | KD1: FY26
B2: Scenario | C2: Actual | D2: Actual | E2: Actual | F2: Actual | G2: Actual | H2: Actual | I2: Actual | J2: Actual | K2: Actual | L2: Actual | M2: Actual | N2: Actual | O2: Actual | P2: Actual | Q2: Actual | R2: Actual | S2: Actual | T2: Actual | U2: Actual | V2: Actual | W2: Actual | X2: Actual | Y2: Actual | Z2: Actual | AA2: Actual | AB2: Actual | AC2: Actual | AD2: Actual | AE2: Actual | AF2: Actual | AG2: Actual | AH2: Actual | AI2: Actual | AJ2: Actual | AK2: Actual | AL2: Actual | AM2: Actual | AN2: Actual | AO2: Actual | AP2: Actual | AQ2: Actual | AR2: Actual | AS2: Actual | AT2: Actual | AU2: Actual | AV2: Actual | AW2: Actual | AX2: Actual | AY2: Actual | AZ2: Actual | BA2: Actual | BB2: Actual | BC2: Actual | BD2: Actual | BE2: Actual | BF2: Actual | BG2: Actual | BH2: Actual | BI2: Actual | BJ2: Actual | BK2: Actual | BL2: Actual | BM2: Actual | BN2: Actual | BO2: Actual | BP2: Actual | BQ2: Actual | BR2: Actual | BS2: Actual | BT2: Actual | BU2: Actual | BV2: Actual | BW2: Actual | BX2: Actual | BY2: Actual | BZ2: Actual | CA2: Actual | CB2: Actual | CC2: Actual | CD2: Actual | CE2: Actual | CF2: Actual | CG2: Actual | CH2: Actual | CI2: Actual | CJ2: Actual | CK2: Actual | CL2: Actual | CM2: Actual | CN2: Actual | CO2: Actual | CP2: Actual | CQ2: Actual | CR2: Actual | CS2: Actual | CT2: Actual | CU2: Actual | CV2: Actual | CW2: Actual | CX2: Actual | CY2: Actual | CZ2: Actual | DA2: Actual | DB2: Actual | DC2: Actual | DD2: Actual | DE2: Actual | DF2: Actual | DG2: Actual | DH2: Actual | DI2: Actual | DJ2: Actual | DK2: Actual | DL2: Actual | DM2: Actual | DN2: Actual | DO2: Actual | DP2: Actual | DQ2: Actual | DR2: Actual | DS2: Actual | DT2: Actual | DU2: Actual | DV2: Actual | DW2: Actual | DX2: Actual | DY2: Actual | DZ2: Actual | EA2: Actual | EB2: Actual | EC2: Actual | ED2: Actual | EE2: Actual | EF2: Actual | EG2: Actual | EH2: Actual | EI2: Actual | EJ2: Actual | EK2: Actual | EL2: Actual | EM2: Actual | EN2: Actual | EO2: Actual | EP2: Actual | EQ2: Actual | ER2: Actual | ES2: Actual | ET2: Actual | EU2: Actual | EV2: Actual | EW2: Actual | EX2: Actual | EY2: Actual | EZ2: Actual | FA2: Actual | FB2: Actual | FC2: Actual | FD2: Actual | FE2: Actual | FF2: Actual | FG2: Actual | FH2: Actual | FI2: Actual | FJ2: Actual | FK2: Actual | FL2: Actual | FM2: Actual | FN2: Actual | FO2: Actual | FP2: Actual | FQ2: Actual | FR2: Actual | FS2: Actual | FT2: Actual | FU2: Actual | FV2: Actual | FW2: Actual | FX2: Actual | FY2: Actual | FZ2: Actual | GA2: Actual | GB2: Actual | GC2: Actual | GD2: Actual | GE2: Actual | GF2: Actual | GG2: Actual | GH2: Actual | GI2: Actual | GJ2: Actual | GK2: Actual | GL2: Actual | GM2: Budget1 | GN2: Budget1 | GO2: Budget1 | GP2: Budget1 | GQ2: Budget1 | GR2: Budget1 | GS2: Budget1 | GT2: Budget1 | GU2: Budget1 | GV2: Budget1 | GW2: Budget1 | GX2: Budget1 | GY2: Budget1 | GZ2: Budget1 | HA2: Budget1 | HB2: Budget1 | HC2: Budget1 | HD2: Budget1 | HE2: Budget1 | HF2: Budget1 | HG2: Budget1 | HH2: Budget1 | HI2: Budget1 | HJ2: Budget1 | HK2: Budget1 | HL2: Budget1 | HM2: Budget1 | HN2: Budget1 | HO2: Budget1 | HP2: Budget1 | HQ2: Budget1 | HR2: Budget1 | HS2: Budget1 | HT2: Budget1 | HU2: Budget1 | HV2: Budget1 | HW2: Budget1 | HX2: Budget1 | HY2: Budget1 | HZ2: Budget1 | IA2: Budget1 | IB2: Budget1 | IC2: Budget1 | ID2: Budget1 | IE2: Budget1 | IF2: Budget1 | IG2: Budget1 | IH2: Budget1 | II2: Budget1 | IJ2: Budget1 | IK2: Budget1 | IL2: Budget1 | IM2: Budget1 | IN2: Budget1 | IO2: Budget1 | IP2: Budget1 | IQ2: Budget1 | IR2: Budget1 | IS2: Budget1 | IT2: Budget1 | IU2: Budget1 | IV2: Budget1 | IW2: Budget1 | IX2: Budget1 | IY2: Budget1 | IZ2: Budget1 | JA2: Budget1 | JB2: Budget1 | JC2: Budget1 | JD2: Budget1 | JE2: Budget1 | JF2: Budget1 | JG2: Budget1 | JH2: Budget1 | JI2: Budget1 | JJ2: Budget1 | JK2: Budget1 | JL2: Budget1 | JM2: Budget1 | JN2: Budget1 | JO2: Budget1 | JP2: Budget1 | JQ2: Budget1 | JR2: Budget1 | JS2: Budget1 | JT2: Budget1 | JU2: Budget1 | JV2: Budget1 | JW2: Budget1 | JX2: Budget1 | JY2: Budget1 | JZ2: Budget1 | KA2: Budget1 | KB2: Budget1 | KC2: Budget1 | KD2: Budget1
B3: Period | C3: Oct | D3: Nov | E3: Dec | F3: Jan | G3: Feb | H3: Mar | I3: Apr | J3: May | K3: Jun | L3: Jul | M3: Aug | N3: Sep | O3: Oct | P3: Nov | Q3: Dec | R3: Jan | S3: Feb | T3: Mar | U3: Apr | V3: May | W3: Jun | X3: Jul | Y3: Aug | Z3: Sep | AA3: Oct | AB3: Nov | AC3: Dec | AD3: Jan | AE3: Feb | AF3: Mar | AG3: Apr | AH3: May | AI3: Jun | AJ3: Jul | AK3: Aug | AL3: Sep | AM3: Oct | AN3: Nov | AO3: Dec | AP3: Jan | AQ3: Feb | AR3: Mar | AS3: Apr | AT3: May | AU3: Jun | AV3: Jul | AW3: Aug | AX3: Sep | AY3: Oct | AZ3: Nov | BA3: Dec | BB3: Jan | BC3: Feb | BD3: Mar | BE3: Apr | BF3: May | BG3: Jun | BH3: Jul | BI3: Aug | BJ3: Sep | BK3: Oct | BL3: Nov | BM3: Dec | BN3: Jan | BO3: Feb | BP3: Mar | BQ3: Apr | BR3: May | BS3: Jun | BT3: Jul | BU3: Aug | BV3: Sep | BW3: Oct | BX3: Nov | BY3: Dec | BZ3: Jan | CA3: Feb | CB3: Mar | CC3: Apr | CD3: May | CE3: Jun | CF3: Jul | CG3: Aug | CH3: Sep | CI3: Oct | CJ3: Nov | CK3: Dec | CL3: Jan | CM3: Feb | CN3: Mar | CO3: Apr | CP3: May | CQ3: Jun | CR3: Jul | CS3: Aug | CT3: Sep | CU3: Oct | CV3: Nov | CW3: Dec | CX3: Jan | CY3: Feb | CZ3: Mar | DA3: Apr | DB3: May | DC3: Jun | DD3: Jul | DE3: Aug | DF3: Sep | DG3: Oct | DH3: Nov | DI3: Dec | DJ3: Jan | DK3: Feb | DL3: Mar | DM3: Apr | DN3: May | DO3: Jun | DP3: Jul | DQ3: Aug | DR3: Sep | DS3: Oct | DT3: Nov | DU3: Dec | DV3: Jan | DW3: Feb | DX3: Mar | DY3: Apr | DZ3: May | EA3: Jun | EB3: Jul | EC3: Aug | ED3: Sep | EE3: Oct | EF3: Nov | EG3: Dec | EH3: Jan | EI3: Feb | EJ3: Mar | EK3: Apr | EL3: May | EM3: Jun | EN3: Jul | EO3: Aug | EP3: Sep | EQ3: Oct | ER3: Nov | ES3: Dec | ET3: Jan | EU3: Feb | EV3: Mar | EW3: Apr | EX3: May | EY3: Jun | EZ3: Jul | FA3: Aug | FB3: Sep | FC3: Oct | FD3: Nov | FE3: Dec | FF3: Jan | FG3: Feb | FH3: Mar | FI3: Apr | FJ3: May | FK3: Jun | FL3: Jul | FM3: Aug | FN3: Sep | FO3: Oct | FP3: Nov | FQ3: Dec | FR3: Jan | FS3: Feb | FT3: Mar | FU3: Apr | FV3: May | FW3: Jun | FX3: Jul | FY3: Aug | FZ3: Sep | GA3: Oct | GB3: Nov | GC3: Dec | GD3: Jan | GE3: Feb | GF3: Mar | GG3: Apr | GH3: May | GI3: Jun | GJ3: Jul | GK3: Aug | GL3: Sep | GM3: Oct | GN3: Nov | GO3: Dec | GP3: Jan | GQ3: Feb | GR3: Mar | GS3: Apr | GT3: May | GU3: Jun | GV3: Jul | GW3: Aug | GX3: Sep | GY3: Oct | GZ3: Nov | HA3: Dec | HB3: Jan | HC3: Feb | HD3: Mar | HE3: Apr | HF3: May | HG3: Jun | HH3: Jul | HI3: Aug | HJ3: Sep | HK3: Oct | HL3: Nov | HM3: Dec | HN3: Jan | HO3: Feb | HP3: Mar | HQ3: Apr | HR3: May | HS3: Jun | HT3: Jul | HU3: Aug | HV3: Sep | HW3: Oct | HX3: Nov | HY3: Dec | HZ3: Jan | IA3: Feb | IB3: Mar | IC3: Apr | ID3: May | IE3: Jun | IF3: Jul | IG3: Aug | IH3: Sep | II3: Oct | IJ3: Nov | IK3: Dec | IL3: Jan | IM3: Feb | IN3: Mar | IO3: Apr | IP3: May | IQ3: Jun | IR3: Jul | IS3: Aug | IT3: Sep | IU3: Oct | IV3: Nov | IW3: Dec | IX3: Jan | IY3: Feb | IZ3: Mar | JA3: Apr | JB3: May | JC3: Jun | JD3: Jul | JE3: Aug | JF3: Sep | JG3: Oct | JH3: Nov | JI3: Dec | JJ3: Jan | JK3: Feb | JL3: Mar | JM3: Apr | JN3: May | JO3: Jun | JP3: Jul | JQ3: Aug | JR3: Sep | JS3: Oct | JT3: Nov | JU3: Dec | JV3: Jan | JW3: Feb | JX3: Mar | JY3: Apr | JZ3: May | KA3: Jun | KB3: Jul | KC3: Aug | KD3: Sep
A4: BL | B4: CC/Key | C4: WCW | D4: WCW | E4: WCW | F4: WCW | G4: WCW | H4: WCW | I4: WCW | J4: WCW | K4: WCW | L4: WCW | M4: WCW | N4: WCW | O4: SAM | P4: SAM | Q4: SAM | R4: SAM | S4: SAM | T4: SAM | U4: SAM | V4: SAM | W4: SAM | X4: SAM | Y4: SAM | Z4: SAM | AA4: Win Acc | AB4: Win Acc | AC4: Win Acc | AD4: Win Acc | AE4: Win Acc | AF4: Win Acc | AG4: Win Acc | AH4: Win Acc | AI4: Win Acc | AJ4: Win Acc | AK4: Win Acc | AL4: Win Acc | AM4: 480056 Cycle | AN4: 480056 Cycle | AO4: 480056 Cycle | AP4: 480056 Cycle | AQ4: 480056 Cycle | AR4: 480056 Cycle | AS4: 480056 Cycle | AT4: 480056 Cycle | AU4: 480056 Cycle | AV4: 480056 Cycle | AW4: 480056 Cycle | AX4: 480056 Cycle | AY4: Headcount | AZ4: Headcount | BA4: Headcount | BB4: Headcount | BC4: Headcount | BD4: Headcount | BE4: Headcount | BF4: Headcount | BG4: Headcount | BH4: Headcount | BI4: Headcount | BJ4: Headcount | BK4: 480055 Cycle | BL4: 480055 Cycle | BM4: 480055 Cycle | BN4: 480055 Cycle | BO4: 480055 Cycle | BP4: 480055 Cycle | BQ4: 480055 Cycle | BR4: 480055 Cycle | BS4: 480055 Cycle | BT4: 480055 Cycle | BU4: 480055 Cycle | BV4: 480055 Cycle | BW4: IM | BX4: IM | BY4: IM | BZ4: IM | CA4: IM | CB4: IM | CC4: IM | CD4: IM | CE4: IM | CF4: IM | CG4: IM | CH4: IM | CI4: Pooling | CJ4: Pooling | CK4: Pooling | CL4: Pooling | CM4: Pooling | CN4: Pooling | CO4: Pooling | CP4: Pooling | CQ4: Pooling | CR4: Pooling | CS4: Pooling | CT4: Pooling | CU4: WCW | CV4: WCW | CW4: WCW | CX4: WCW | CY4: WCW | CZ4: WCW | DA4: WCW | DB4: WCW | DC4: WCW | DD4: WCW | DE4: WCW | DF4: WCW | DG4: SAM | DH4: SAM | DI4: SAM | DJ4: SAM | DK4: SAM | DL4: SAM | DM4: SAM | DN4: SAM | DO4: SAM | DP4: SAM | DQ4: SAM | DR4: SAM | DS4: Win Acc | DT4: Win Acc | DU4: Win Acc | DV4: Win Acc | DW4: Win Acc | DX4: Win Acc | DY4: Win Acc | DZ4: Win Acc | EA4: Win Acc | EB4: Win Acc | EC4: Win Acc | ED4: Win Acc | EE4: 480056 Cycle | EF4: 480056 Cycle | EG4: 480056 Cycle | EH4: 480056 Cycle | EI4: 480056 Cycle | EJ4: 480056 Cycle | EK4: 480056 Cycle | EL4: 480056 Cycle | EM4: 480056 Cycle | EN4: 480056 Cycle | EO4: 480056 Cycle | EP4: 480056 Cycle | EQ4: Headcount | ER4: Headcount | ES4: Headcount | ET4: Headcount | EU4: Headcount | EV4: Headcount | EW4: Headcount | EX4: Headcount | EY4: Headcount | EZ4: Headcount | FA4: Headcount | FB4: Headcount | FC4: 480055 Cycle | FD4: 480055 Cycle | FE4: 480055 Cycle | FF4: 480055 Cycle | FG4: 480055 Cycle | FH4: 480055 Cycle | FI4: 480055 Cycle | FJ4: 480055 Cycle | FK4: 480055 Cycle | FL4: 480055 Cycle | FM4: 480055 Cycle | FN4: 480055 Cycle | FO4: IM | FP4: IM | FQ4: IM | FR4: IM | FS4: IM | FT4: IM | FU4: IM | FV4: IM | FW4: IM | FX4: IM | FY4: IM | FZ4: IM | GA4: Pooling | GB4: Pooling | GC4: Pooling | GD4: Pooling | GE4: Pooling | GF4: Pooling | GG4: Pooling | GH4: Pooling | GI4: Pooling | GJ4: Pooling | GK4: Pooling | GL4: Pooling | GM4: WCW | GN4: WCW | GO4: WCW | GP4: WCW | GQ4: WCW | GR4: WCW | GS4: WCW | GT4: WCW | GU4: WCW | GV4: WCW | GW4: WCW | GX4: WCW | GY4: SAM | GZ4: SAM | HA4: SAM | HB4: SAM | HC4: SAM | HD4: SAM | HE4: SAM | HF4: SAM | HG4: SAM | HH4: SAM | HI4: SAM | HJ4: SAM | HK4: Win Acc | HL4: Win Acc | HM4: Win Acc | HN4: Win Acc | HO4: Win Acc | HP4: Win Acc | HQ4: Win Acc | HR4: Win Acc | HS4: Win Acc | HT4: Win Acc | HU4: Win Acc | HV4: Win Acc | HW4: 480056 Cycle | HX4: 480056 Cycle | HY4: 480056 Cycle | HZ4: 480056 Cycle | IA4: 480056 Cycle | IB4: 480056 Cycle | IC4: 480056 Cycle | ID4: 480056 Cycle | IE4: 480056 Cycle | IF4: 480056 Cycle | IG4: 480056 Cycle | IH4: 480056 Cycle | II4: Headcount | IJ4: Headcount | IK4: Headcount | IL4: Headcount | IM4: Headcount | IN4: Headcount | IO4: Headcount | IP4: Headcount | IQ4: Headcount | IR4: Headcount | IS4: Headcount | IT4: Headcount | IU4: 480055 Cycle | IV4: 480055 Cycle | IW4: 480055 Cycle | IX4: 480055 Cycle | IY4: 480055 Cycle | IZ4: 480055 Cycle | JA4: 480055 Cycle | JB4: 480055 Cycle | JC4: 480055 Cycle | JD4: 480055 Cycle | JE4: 480055 Cycle | JF4: 480055 Cycle | JG4: IM | JH4: IM | JI4: IM | JJ4: IM | JK4: IM | JL4: IM | JM4: IM | JN4: IM | JO4: IM | JP4: IM | JQ4: IM | JR4: IM | JS4: Pooling | JT4: Pooling | JU4: Pooling | JV4: Pooling | JW4: Pooling | JX4: Pooling | JY4: Pooling | JZ4: Pooling | KA4: Pooling | KB4: Pooling | KC4: Pooling | KD4: Pooling
A5: BL | B5: CC | C5: FY24-Actual-Oct-WCW | D5: FY24-Actual-Nov-WCW | E5: FY24-Actual-Dec-WCW | F5: FY24-Actual-Jan-WCW | G5: FY24-Actual-Feb-WCW | H5: FY24-Actual-Mar-WCW | I5: FY24-Actual-Apr-WCW | J5: FY24-Actual-May-WCW | K5: FY24-Actual-Jun-WCW | L5: FY24-Actual-Jul-WCW | M5: FY24-Actual-Aug-WCW | N5: FY24-Actual-Sep-WCW | O5: FY24-Actual-Oct-SAM | P5: FY24-Actual-Nov-SAM | Q5: FY24-Actual-Dec-SAM | R5: FY24-Actual-Jan-SAM | S5: FY24-Actual-Feb-SAM | T5: FY24-Actual-Mar-SAM | U5: FY24-Actual-Apr-SAM | V5: FY24-Actual-May-SAM | W5: FY24-Actual-Jun-SAM | X5: FY24-Actual-Jul-SAM | Y5: FY24-Actual-Aug-SAM | Z5: FY24-Actual-Sep-SAM | AA5: FY24-Actual-Oct-Win Acc | AB5: FY24-Actual-Nov-Win Acc | AC5: FY24-Actual-Dec-Win Acc | AD5: FY24-Actual-Jan-Win Acc | AE5: FY24-Actual-Feb-Win Acc | AF5: FY24-Actual-Mar-Win Acc | AG5: FY24-Actual-Apr-Win Acc | AH5: FY24-Actual-May-Win Acc | AI5: FY24-Actual-Jun-Win Acc | AJ5: FY24-Actual-Jul-Win Acc | AK5: FY24-Actual-Aug-Win Acc | AL5: FY24-Actual-Sep-Win Acc | AM5: FY24-Actual-Oct-480056 Cycle | AN5: FY24-Actual-Nov-480056 Cycle | AO5: FY24-Actual-Dec-480056 Cycle | AP5: FY24-Actual-Jan-480056 Cycle | AQ5: FY24-Actual-Feb-480056 Cycle | AR5: FY24-Actual-Mar-480056 Cycle | AS5: FY24-Actual-Apr-480056 Cycle | AT5: FY24-Actual-May-480056 Cycle | AU5: FY24-Actual-Jun-480056 Cycle | AV5: FY24-Actual-Jul-480056 Cycle | AW5: FY24-Actual-Aug-480056 Cycle | AX5: FY24-Actual-Sep-480056 Cycle | AY5: FY24-Actual-Oct-Headcount | AZ5: FY24-Actual-Nov-Headcount | BA5: FY24-Actual-Dec-Headcount | BB5: FY24-Actual-Jan-Headcount | BC5: FY24-Actual-Feb-Headcount | BD5: FY24-Actual-Mar-Headcount | BE5: FY24-Actual-Apr-Headcount | BF5: FY24-Actual-May-Headcount | BG5: FY24-Actual-Jun-Headcount | BH5: FY24-Actual-Jul-Headcount | BI5: FY24-Actual-Aug-Headcount | BJ5: FY24-Actual-Sep-Headcount | BK5: FY24-Actual-Oct-480055 Cycle | BL5: FY24-Actual-Nov-480055 Cycle | BM5: FY24-Actual-Dec-480055 Cycle | BN5: FY24-Actual-Jan-480055 Cycle | BO5: FY24-Actual-Feb-480055 Cycle | BP5: FY24-Actual-Mar-480055 Cycle | BQ5: FY24-Actual-Apr-480055 Cycle | BR5: FY24-Actual-May-480055 Cycle | BS5: FY24-Actual-Jun-480055 Cycle | BT5: FY24-Actual-Jul-480055 Cycle | BU5: FY24-Actual-Aug-480055 Cycle | BV5: FY24-Actual-Sep-480055 Cycle | BW5: FY24-Actual-Oct-IM | BX5: FY24-Actual-Nov-IM | BY5: FY24-Actual-Dec-IM | BZ5: FY24-Actual-Jan-IM | CA5: FY24-Actual-Feb-IM | CB5: FY24-Actual-Mar-IM | CC5: FY24-Actual-Apr-IM | CD5: FY24-Actual-May-IM | CE5: FY24-Actual-Jun-IM | CF5: FY24-Actual-Jul-IM | CG5: FY24-Actual-Aug-IM | CH5: FY24-Actual-Sep-IM | CI5: FY24-Actual-Oct-Pooling | CJ5: FY24-Actual-Nov-Pooling | CK5: FY24-Actual-Dec-Pooling | CL5: FY24-Actual-Jan-Pooling | CM5: FY24-Actual-Feb-Pooling | CN5: FY24-Actual-Mar-Pooling | CO5: FY24-Actual-Apr-Pooling | CP5: FY24-Actual-May-Pooling | CQ5: FY24-Actual-Jun-Pooling | CR5: FY24-Actual-Jul-Pooling | CS5: FY24-Actual-Aug-Pooling | CT5: FY24-Actual-Sep-Pooling | CU5: FY25-Actual-Oct-WCW | CV5: FY25-Actual-Nov-WCW | CW5: FY25-Actual-Dec-WCW | CX5: FY25-Actual-Jan-WCW | CY5: FY25-Actual-Feb-WCW | CZ5: FY25-Actual-Mar-WCW | DA5: FY25-Actual-Apr-WCW | DB5: FY25-Actual-May-WCW | DC5: FY25-Actual-Jun-WCW | DD5: FY25-Actual-Jul-WCW | DE5: FY25-Actual-Aug-WCW | DF5: FY25-Actual-Sep-WCW | DG5: FY25-Actual-Oct-SAM | DH5: FY25-Actual-Nov-SAM | DI5: FY25-Actual-Dec-SAM | DJ5: FY25-Actual-Jan-SAM | DK5: FY25-Actual-Feb-SAM | DL5: FY25-Actual-Mar-SAM | DM5: FY25-Actual-Apr-SAM | DN5: FY25-Actual-May-SAM | DO5: FY25-Actual-Jun-SAM | DP5: FY25-Actual-Jul-SAM | DQ5: FY25-Actual-Aug-SAM | DR5: FY25-Actual-Sep-SAM | DS5: FY25-Actual-Oct-Win Acc | DT5: FY25-Actual-Nov-Win Acc | DU5: FY25-Actual-Dec-Win Acc | DV5: FY25-Actual-Jan-Win Acc | DW5: FY25-Actual-Feb-Win Acc | DX5: FY25-Actual-Mar-Win Acc | DY5: FY25-Actual-Apr-Win Acc | DZ5: FY25-Actual-May-Win Acc | EA5: FY25-Actual-Jun-Win Acc | EB5: FY25-Actual-Jul-Win Acc | EC5: FY25-Actual-Aug-Win Acc | ED5: FY25-Actual-Sep-Win Acc | EE5: FY25-Actual-Oct-480056 Cycle | EF5: FY25-Actual-Nov-480056 Cycle | EG5: FY25-Actual-Dec-480056 Cycle | EH5: FY25-Actual-Jan-480056 Cycle | EI5: FY25-Actual-Feb-480056 Cycle | EJ5: FY25-Actual-Mar-480056 Cycle | EK5: FY25-Actual-Apr-480056 Cycle | EL5: FY25-Actual-May-480056 Cycle | EM5: FY25-Actual-Jun-480056 Cycle | EN5: FY25-Actual-Jul-480056 Cycle | EO5: FY25-Actual-Aug-480056 Cycle | EP5: FY25-Actual-Sep-480056 Cycle | EQ5: FY25-Actual-Oct-Headcount | ER5: FY25-Actual-Nov-Headcount | ES5: FY25-Actual-Dec-Headcount | ET5: FY25-Actual-Jan-Headcount | EU5: FY25-Actual-Feb-Headcount | EV5: FY25-Actual-Mar-Headcount | EW5: FY25-Actual-Apr-Headcount | EX5: FY25-Actual-May-Headcount | EY5: FY25-Actual-Jun-Headcount | EZ5: FY25-Actual-Jul-Headcount | FA5: FY25-Actual-Aug-Headcount | FB5: FY25-Actual-Sep-Headcount | FC5: FY25-Actual-Oct-480055 Cycle | FD5: FY25-Actual-Nov-480055 Cycle | FE5: FY25-Actual-Dec-480055 Cycle | FF5: FY25-Actual-Jan-480055 Cycle | FG5: FY25-Actual-Feb-480055 Cycle | FH5: FY25-Actual-Mar-480055 Cycle | FI5: FY25-Actual-Apr-480055 Cycle | FJ5: FY25-Actual-May-480055 Cycle | FK5: FY25-Actual-Jun-480055 Cycle | FL5: FY25-Actual-Jul-480055 Cycle | FM5: FY25-Actual-Aug-480055 Cycle | FN5: FY25-Actual-Sep-480055 Cycle | FO5: FY25-Actual-Oct-IM | FP5: FY25-Actual-Nov-IM | FQ5: FY25-Actual-Dec-IM | FR5: FY25-Actual-Jan-IM | FS5: FY25-Actual-Feb-IM | FT5: FY25-Actual-Mar-IM | FU5: FY25-Actual-Apr-IM | FV5: FY25-Actual-May-IM | FW5: FY25-Actual-Jun-IM | FX5: FY25-Actual-Jul-IM | FY5: FY25-Actual-Aug-IM | FZ5: FY25-Actual-Sep-IM | GA5: FY25-Actual-Oct-Pooling | GB5: FY25-Actual-Nov-Pooling | GC5: FY25-Actual-Dec-Pooling | GD5: FY25-Actual-Jan-Pooling | GE5: FY25-Actual-Feb-Pooling | GF5: FY25-Actual-Mar-Pooling | GG5: FY25-Actual-Apr-Pooling | GH5: FY25-Actual-May-Pooling | GI5: FY25-Actual-Jun-Pooling | GJ5: FY25-Actual-Jul-Pooling | GK5: FY25-Actual-Aug-Pooling | GL5: FY25-Actual-Sep-Pooling | GM5: FY26-Budget1-Oct-WCW | GN5: FY26-Budget1-Nov-WCW | GO5: FY26-Budget1-Dec-WCW | GP5: FY26-Budget1-Jan-WCW | GQ5: FY26-Budget1-Feb-WCW | GR5: FY26-Budget1-Mar-WCW | GS5: FY26-Budget1-Apr-WCW | GT5: FY26-Budget1-May-WCW | GU5: FY26-Budget1-Jun-WCW | GV5: FY26-Budget1-Jul-WCW | GW5: FY26-Budget1-Aug-WCW | GX5: FY26-Budget1-Sep-WCW | GY5: FY26-Budget1-Oct-SAM | GZ5: FY26-Budget1-Nov-SAM | HA5: FY26-Budget1-Dec-SAM | HB5: FY26-Budget1-Jan-SAM | HC5: FY26-Budget1-Feb-SAM | HD5: FY26-Budget1-Mar-SAM | HE5: FY26-Budget1-Apr-SAM | HF5: FY26-Budget1-May-SAM | HG5: FY26-Budget1-Jun-SAM | HH5: FY26-Budget1-Jul-SAM | HI5: FY26-Budget1-Aug-SAM | HJ5: FY26-Budget1-Sep-SAM | HK5: FY26-Budget1-Oct-Win Acc | HL5: FY26-Budget1-Nov-Win Acc | HM5: FY26-Budget1-Dec-Win Acc | HN5: FY26-Budget1-Jan-Win Acc | HO5: FY26-Budget1-Feb-Win Acc | HP5: FY26-Budget1-Mar-Win Acc | HQ5: FY26-Budget1-Apr-Win Acc | HR5: FY26-Budget1-May-Win Acc | HS5: FY26-Budget1-Jun-Win Acc | HT5: FY26-Budget1-Jul-Win Acc | HU5: FY26-Budget1-Aug-Win Acc | HV5: FY26-Budget1-Sep-Win Acc | HW5: FY26-Budget1-Oct-480056 Cycle | HX5: FY26-Budget1-Nov-480056 Cycle | HY5: FY26-Budget1-Dec-480056 Cycle | HZ5: FY26-Budget1-Jan-480056 Cycle | IA5: FY26-Budget1-Feb-480056 Cycle | IB5: FY26-Budget1-Mar-480056 Cycle | IC5: FY26-Budget1-Apr-480056 Cycle | ID5: FY26-Budget1-May-480056 Cycle | IE5: FY26-Budget1-Jun-480056 Cycle | IF5: FY26-Budget1-Jul-480056 Cycle | IG5: FY26-Budget1-Aug-480056 Cycle | IH5: FY26-Budget1-Sep-480056 Cycle | II5: FY26-Budget1-Oct-Headcount | IJ5: FY26-Budget1-Nov-Headcount | IK5: FY26-Budget1-Dec-Headcount | IL5: FY26-Budget1-Jan-Headcount | IM5: FY26-Budget1-Feb-Headcount | IN5: FY26-Budget1-Mar-Headcount | IO5: FY26-Budget1-Apr-Headcount | IP5: FY26-Budget1-May-Headcount | IQ5: FY26-Budget1-Jun-Headcount | IR5: FY26-Budget1-Jul-Headcount | IS5: FY26-Budget1-Aug-Headcount | IT5: FY26-Budget1-Sep-Headcount | IU5: FY26-Budget1-Oct-480055 Cycle | IV5: FY26-Budget1-Nov-480055 Cycle | IW5: FY26-Budget1-Dec-480055 Cycle | IX5: FY26-Budget1-Jan-480055 Cycle | IY5: FY26-Budget1-Feb-480055 Cycle | IZ5: FY26-Budget1-Mar-480055 Cycle | JA5: FY26-Budget1-Apr-480055 Cycle | JB5: FY26-Budget1-May-480055 Cycle | JC5: FY26-Budget1-Jun-480055 Cycle | JD5: FY26-Budget1-Jul-480055 Cycle | JE5: FY26-Budget1-Aug-480055 Cycle | JF5: FY26-Budget1-Sep-480055 Cycle | JG5: FY26-Budget1-Oct-IM | JH5: FY26-Budget1-Nov-IM | JI5: FY26-Budget1-Dec-IM | JJ5: FY26-Budget1-Jan-IM | JK5: FY26-Budget1-Feb-IM | JL5: FY26-Budget1-Mar-IM | JM5: FY26-Budget1-Apr-IM | JN5: FY26-Budget1-May-IM | JO5: FY26-Budget1-Jun-IM | JP5: FY26-Budget1-Jul-IM | JQ5: FY26-Budget1-Aug-IM | JR5: FY26-Budget1-Sep-IM | JS5: FY26-Budget1-Oct-Pooling | JT5: FY26-Budget1-Nov-Pooling | JU5: FY26-Budget1-Dec-Pooling | JV5: FY26-Budget1-Jan-Pooling | JW5: FY26-Budget1-Feb-Pooling | JX5: FY26-Budget1-Mar-Pooling | JY5: FY26-Budget1-Apr-Pooling | JZ5: FY26-Budget1-May-Pooling | KA5: FY26-Budget1-Jun-Pooling | KB5: FY26-Budget1-Jul-Pooling | KC5: FY26-Budget1-Aug-Pooling | KD5: FY26-Budget1-Sep-Pooling
A6: =VLOOKUP(B6,'CC Mapping'!$A:$B,2,0) -> CT | B6: 412011 | C6: 0.2056 | D6: =C6 -> 0.2056 | E6: =D6 -> 0.2056 | F6: =E6 -> 0.2056 | G6: =F6 -> 0.2056 | H6: =G6 -> 0.2056 | I6: =H6 -> 0.2056 | J6: =I6 -> 0.2056 | K6: =J6 -> 0.2056 | ... N6: =M6 -> 0.2056 | O6: 0.1981 | P6: =O6 -> 0.1981 | Q6: =P6 -> 0.1981 | R6: =Q6 -> 0.1981 | S6: =R6 -> 0.1981 | T6: =S6 -> 0.1981 | U6: =T6 -> 0.1981 | V6: =U6 -> 0.1981 | W6: =V6 -> 0.1981 | ... Z6: =Y6 -> 0.1981 | AA6: 0.1705 | AB6: =AA6 -> 0.1705 | AC6: =AB6 -> 0.1705 | AD6: =AC6 -> 0.1705 | AE6: =AD6 -> 0.1705 | AF6: =AE6 -> 0.1705 | AG6: =AF6 -> 0.1705 | AH6: =AG6 -> 0.1705 | AI6: =AH6 -> 0.1705 | ... AL6: =AK6 -> 0.1705 | AM6: 0.19642202 | AN6: =AM6 -> 0.19642202 | AO6: =AN6 -> 0.19642202 | AP6: =AO6 -> 0.19642202 | AQ6: =AP6 -> 0.19642202 | AR6: =AQ6 -> 0.19642202 | AS6: =AR6 -> 0.19642202 | AT6: =AS6 -> 0.19642202 | AU6: =AT6 -> 0.19642202 | ... AX6: =AW6 -> 0.19642202 | AY6: 0.1547 | AZ6: =AY6 -> 0.1547 | BA6: =AZ6 -> 0.1547 | BB6: =BA6 -> 0.1547 | BC6: =BB6 -> 0.1547 | BD6: =BC6 -> 0.1547 | BE6: =BD6 -> 0.1547 | BF6: =BE6 -> 0.1547 | BG6: =BF6 -> 0.1547 | ... BJ6: =BI6 -> 0.1547 | BK6: 0.1547 | BL6: =BK6 -> 0.1547 | BM6: =BL6 -> 0.1547 | BN6: =BM6 -> 0.1547 | BO6: =BN6 -> 0.1547 | BP6: =BO6 -> 0.1547 | BQ6: =BP6 -> 0.1547 | BR6: =BQ6 -> 0.1547 | BS6: =BR6 -> 0.1547 | ... BV6: =BU6 -> 0.1547 | BW6: 0 | BX6: =BW6 -> 0 | BY6: =BX6 -> 0 | BZ6: =BY6 -> 0 | CA6: =BZ6 -> 0 | CB6: =CA6 -> 0 | CC6: =CB6 -> 0 | CD6: =CC6 -> 0 | CE6: =CD6 -> 0 | ... CH6: =CG6 -> 0 | CI6: 0 | CJ6: =CI6 -> 0 | CK6: =CJ6 -> 0 | CL6: =CK6 -> 0 | CM6: =CL6 -> 0 | CN6: =CM6 -> 0 | CO6: =CN6 -> 0 | CP6: =CO6 -> 0 | CQ6: =CP6 -> 0 | ... CT6: =CS6 -> 0 | CU6: 0.2346 | CV6: =CU6 -> 0.2346 | CW6: =CV6 -> 0.2346 | CX6: =CW6 -> 0.2346 | CY6: =CX6 -> 0.2346 | CZ6: =CY6 -> 0.2346 | DA6: =CZ6 -> 0.2346 | DB6: =DA6 -> 0.2346 | DC6: =DB6 -> 0.2346 | ... DF6: =DE6 -> 0.2346 | DG6: 0.2009 | DH6: =DG6 -> 0.2009 | DI6: =DH6 -> 0.2009 | DJ6: =DI6 -> 0.2009 | DK6: =DJ6 -> 0.2009 | DL6: =DK6 -> 0.2009 | DM6: =DL6 -> 0.2009 | DN6: =DM6 -> 0.2009 | DO6: =DN6 -> 0.2009 | ... DR6: =DQ6 -> 0.2009 | DS6: 0.1732 | DT6: =DS6 -> 0.1732 | DU6: =DT6 -> 0.1732 | DV6: =DU6 -> 0.1732 | DW6: =DV6 -> 0.1732 | DX6: =DW6 -> 0.1732 | DY6: =DX6 -> 0.1732 | DZ6: =DY6 -> 0.1732 | EA6: =DZ6 -> 0.1732 | ... ED6: =EC6 -> 0.1732 | EE6: 0.21770842 | EF6: =EE6 -> 0.21770842 | EG6: =EF6 -> 0.21770842 | EH6: =EG6 -> 0.21770842 | EI6: =EH6 -> 0.21770842 | EJ6: =EI6 -> 0.21770842 | EK6: =EJ6 -> 0.21770842 | EL6: =EK6 -> 0.21770842 | EM6: =EL6 -> 0.21770842 | ... EP6: =EO6 -> 0.21770842 | EQ6: 0.169 | ER6: =EQ6 -> 0.169 | ES6: =ER6 -> 0.169 | ET6: =ES6 -> 0.169 | EU6: =ET6 -> 0.169 | EV6: =EU6 -> 0.169 | EW6: =EV6 -> 0.169 | EX6: =EW6 -> 0.169 | EY6: =EX6 -> 0.169 | ... FB6: =FA6 -> 0.169 | FC6: =EQ6 -> 0.169 | FD6: =FC6 -> 0.169 | FE6: =FD6 -> 0.169 | FF6: =FE6 -> 0.169 | FG6: =FF6 -> 0.169 | FH6: =FG6 -> 0.169 | FI6: =FH6 -> 0.169 | FJ6: =FI6 -> 0.169 | FK6: =FJ6 -> 0.169 | ... FN6: =FM6 -> 0.169 | FO6: 0 | FP6: =FO6 -> 0 | FQ6: =FP6 -> 0 | FR6: =FQ6 -> 0 | FS6: =FR6 -> 0 | FT6: =FS6 -> 0 | FU6: =FT6 -> 0 | FV6: =FU6 -> 0 | FW6: =FV6 -> 0 | ... FZ6: =FY6 -> 0 | GA6: 0 | GB6: =GA6 -> 0 | GC6: =GB6 -> 0 | GD6: =GC6 -> 0 | GE6: =GD6 -> 0 | GF6: =GE6 -> 0 | GG6: =GF6 -> 0 | GH6: =GG6 -> 0 | GI6: =GH6 -> 0 | ... GL6: =GK6 -> 0 | GM6: 0.229 | GN6: =GM6 -> 0.229 | GO6: =GN6 -> 0.229 | GP6: =GO6 -> 0.229 | GQ6: =GP6 -> 0.229 | GR6: =GQ6 -> 0.229 | GS6: =GR6 -> 0.229 | GT6: =GS6 -> 0.229 | GU6: =GT6 -> 0.229 | ... GX6: =GW6 -> 0.229 | GY6: 0.2297 | GZ6: =GY6 -> 0.2297 | HA6: =GZ6 -> 0.2297 | HB6: =HA6 -> 0.2297 | HC6: =HB6 -> 0.2297 | HD6: =HC6 -> 0.2297 | HE6: =HD6 -> 0.2297 | HF6: =HE6 -> 0.2297 | HG6: =HF6 -> 0.2297 | ... HJ6: =HI6 -> 0.2297 | HK6: 0.1751 | HL6: =HK6 -> 0.1751 | HM6: =HL6 -> 0.1751 | HN6: =HM6 -> 0.1751 | HO6: =HN6 -> 0.1751 | HP6: =HO6 -> 0.1751 | HQ6: =HP6 -> 0.1751 | HR6: =HQ6 -> 0.1751 | HS6: =HR6 -> 0.1751 | ... HV6: =HU6 -> 0.1751 | HW6: 0.22782218 | HX6: =HW6 -> 0.22782218 | HY6: =HX6 -> 0.22782218 | HZ6: =HY6 -> 0.22782218 | IA6: =HZ6 -> 0.22782218 | IB6: =IA6 -> 0.22782218 | IC6: =IB6 -> 0.22782218 | ID6: =IC6 -> 0.22782218 | IE6: =ID6 -> 0.22782218 | ... IH6: =IG6 -> 0.22782218 | II6: 0.166 | IJ6: =II6 -> 0.166 | IK6: =IJ6 -> 0.166 | IL6: =IK6 -> 0.166 | IM6: =IL6 -> 0.166 | IN6: =IM6 -> 0.166 | IO6: =IN6 -> 0.166 | IP6: =IO6 -> 0.166 | IQ6: =IP6 -> 0.166 | ... IT6: =IS6 -> 0.166 | IU6: =II6 -> 0.166 | IV6: =IU6 -> 0.166 | IW6: =IV6 -> 0.166 | IX6: =IW6 -> 0.166 | IY6: =IX6 -> 0.166 | IZ6: =IY6 -> 0.166 | JA6: =IZ6 -> 0.166 | JB6: =JA6 -> 0.166 | JC6: =JB6 -> 0.166 | ... JF6: =JE6 -> 0.166 | JG6: 0 | JH6: =JG6 -> 0 | JI6: =JH6 -> 0 | JJ6: =JI6 -> 0 | JK6: =JJ6 -> 0 | JL6: =JK6 -> 0 | JM6: =JL6 -> 0 | JN6: =JM6 -> 0 | JO6: =JN6 -> 0 | ... JR6: =JQ6 -> 0 | JS6: 0 | JT6: =JS6 -> 0 | JU6: =JT6 -> 0 | JV6: =JU6 -> 0 | JW6: =JV6 -> 0 | JX6: =JW6 -> 0 | JY6: =JX6 -> 0 | JZ6: =JY6 -> 0 | KA6: =JZ6 -> 0 | ... KD6: =KC6 -> 0
A7: =VLOOKUP(B7,'CC Mapping'!$A:$B,2,0) -> CT | B7: 412021 | C7: 0.0385 | D7: =C7 -> 0.0385 | E7: =D7 -> 0.0385 | F7: =E7 -> 0.0385 | G7: =F7 -> 0.0385 | H7: =G7 -> 0.0385 | I7: =H7 -> 0.0385 | J7: =I7 -> 0.0385 | K7: =J7 -> 0.0385 | ... N7: =M7 -> 0.0385 | O7: 0.0214 | P7: =O7 -> 0.0214 | Q7: =P7 -> 0.0214 | R7: =Q7 -> 0.0214 | S7: =R7 -> 0.0214 | T7: =S7 -> 0.0214 | U7: =T7 -> 0.0214 | V7: =U7 -> 0.0214 | W7: =V7 -> 0.0214 | ... Z7: =Y7 -> 0.0214 | AA7: 0.0263 | AB7: =AA7 -> 0.0263 | AC7: =AB7 -> 0.0263 | AD7: =AC7 -> 0.0263 | AE7: =AD7 -> 0.0263 | AF7: =AE7 -> 0.0263 | AG7: =AF7 -> 0.0263 | AH7: =AG7 -> 0.0263 | AI7: =AH7 -> 0.0263 | ... AL7: =AK7 -> 0.0263 | AM7: 0.030141197 | AN7: =AM7 -> 0.030141197 | AO7: =AN7 -> 0.030141197 | AP7: =AO7 -> 0.030141197 | AQ7: =AP7 -> 0.030141197 | AR7: =AQ7 -> 0.030141197 | AS7: =AR7 -> 0.030141197 | AT7: =AS7 -> 0.030141197 | AU7: =AT7 -> 0.030141197 | ... AX7: =AW7 -> 0.030141197 | AY7: 0.0292 | AZ7: =AY7 -> 0.0292 | BA7: =AZ7 -> 0.0292 | BB7: =BA7 -> 0.0292 | BC7: =BB7 -> 0.0292 | BD7: =BC7 -> 0.0292 | BE7: =BD7 -> 0.0292 | BF7: =BE7 -> 0.0292 | BG7: =BF7 -> 0.0292 | ... BJ7: =BI7 -> 0.0292 | BK7: 0.0292 | BL7: =BK7 -> 0.0292 | BM7: =BL7 -> 0.0292 | BN7: =BM7 -> 0.0292 | BO7: =BN7 -> 0.0292 | BP7: =BO7 -> 0.0292 | BQ7: =BP7 -> 0.0292 | BR7: =BQ7 -> 0.0292 | BS7: =BR7 -> 0.0292 | ... BV7: =BU7 -> 0.0292 | BW7: 0 | BX7: =BW7 -> 0 | BY7: =BX7 -> 0 | BZ7: =BY7 -> 0 | CA7: =BZ7 -> 0 | CB7: =CA7 -> 0 | CC7: =CB7 -> 0 | CD7: =CC7 -> 0 | CE7: =CD7 -> 0 | ... CH7: =CG7 -> 0 | CI7: 0 | CJ7: =CI7 -> 0 | CK7: =CJ7 -> 0 | CL7: =CK7 -> 0 | CM7: =CL7 -> 0 | CN7: =CM7 -> 0 | CO7: =CN7 -> 0 | CP7: =CO7 -> 0 | CQ7: =CP7 -> 0 | ... CT7: =CS7 -> 0 | CU7: 0.036 | CV7: =CU7 -> 0.036 | CW7: =CV7 -> 0.036 | CX7: =CW7 -> 0.036 | CY7: =CX7 -> 0.036 | CZ7: =CY7 -> 0.036 | DA7: =CZ7 -> 0.036 | DB7: =DA7 -> 0.036 | DC7: =DB7 -> 0.036 | ... DF7: =DE7 -> 0.036 | DG7: 0.0218 | DH7: =DG7 -> 0.0218 | DI7: =DH7 -> 0.0218 | DJ7: =DI7 -> 0.0218 | DK7: =DJ7 -> 0.0218 | DL7: =DK7 -> 0.0218 | DM7: =DL7 -> 0.0218 | DN7: =DM7 -> 0.0218 | DO7: =DN7 -> 0.0218 | ... DR7: =DQ7 -> 0.0218 | DS7: 0.0286 | DT7: =DS7 -> 0.0286 | DU7: =DT7 -> 0.0286 | DV7: =DU7 -> 0.0286 | DW7: =DV7 -> 0.0286 | DX7: =DW7 -> 0.0286 | DY7: =DX7 -> 0.0286 | DZ7: =DY7 -> 0.0286 | EA7: =DZ7 -> 0.0286 | ... ED7: =EC7 -> 0.0286 | EE7: 0.029396193 | EF7: =EE7 -> 0.029396193 | EG7: =EF7 -> 0.029396193 | EH7: =EG7 -> 0.029396193 | EI7: =EH7 -> 0.029396193 | EJ7: =EI7 -> 0.029396193 | EK7: =EJ7 -> 0.029396193 | EL7: =EK7 -> 0.029396193 | EM7: =EL7 -> 0.029396193 | ... EP7: =EO7 -> 0.029396193 | EQ7: 0.0316 | ER7: =EQ7 -> 0.0316 | ES7: =ER7 -> 0.0316 | ET7: =ES7 -> 0.0316 | EU7: =ET7 -> 0.0316 | EV7: =EU7 -> 0.0316 | EW7: =EV7 -> 0.0316 | EX7: =EW7 -> 0.0316 | EY7: =EX7 -> 0.0316 | ... FB7: =FA7 -> 0.0316 | FC7: =EQ7 -> 0.0316 | FD7: =FC7 -> 0.0316 | FE7: =FD7 -> 0.0316 | FF7: =FE7 -> 0.0316 | FG7: =FF7 -> 0.0316 | FH7: =FG7 -> 0.0316 | FI7: =FH7 -> 0.0316 | FJ7: =FI7 -> 0.0316 | FK7: =FJ7 -> 0.0316 | ... FN7: =FM7 -> 0.0316 | FO7: 0 | FP7: =FO7 -> 0 | FQ7: =FP7 -> 0 | FR7: =FQ7 -> 0 | FS7: =FR7 -> 0 | FT7: =FS7 -> 0 | FU7: =FT7 -> 0 | FV7: =FU7 -> 0 | FW7: =FV7 -> 0 | ... FZ7: =FY7 -> 0 | GA7: 0 | GB7: =GA7 -> 0 | GC7: =GB7 -> 0 | GD7: =GC7 -> 0 | GE7: =GD7 -> 0 | GF7: =GE7 -> 0 | GG7: =GF7 -> 0 | GH7: =GG7 -> 0 | GI7: =GH7 -> 0 | ... GL7: =GK7 -> 0 | GM7: 0.030176 | GN7: =GM7 -> 0.030176 | GO7: =GN7 -> 0.030176 | GP7: =GO7 -> 0.030176 | GQ7: =GP7 -> 0.030176 | GR7: =GQ7 -> 0.030176 | GS7: =GR7 -> 0.030176 | GT7: =GS7 -> 0.030176 | GU7: =GT7 -> 0.030176 | ... GX7: =GW7 -> 0.030176 | GY7: 0.018368 | GZ7: =GY7 -> 0.018368 | HA7: =GZ7 -> 0.018368 | HB7: =HA7 -> 0.018368 | HC7: =HB7 -> 0.018368 | HD7: =HC7 -> 0.018368 | HE7: =HD7 -> 0.018368 | HF7: =HE7 -> 0.018368 | HG7: =HF7 -> 0.018368 | ... HJ7: =HI7 -> 0.018368 | HK7: 0.0268 | HL7: =HK7 -> 0.0268 | HM7: =HL7 -> 0.0268 | HN7: =HM7 -> 0.0268 | HO7: =HN7 -> 0.0268 | HP7: =HO7 -> 0.0268 | HQ7: =HP7 -> 0.0268 | HR7: =HQ7 -> 0.0268 | HS7: =HR7 -> 0.0268 | ... HV7: =HU7 -> 0.0268 | HW7: 0.02433767 | HX7: =HW7 -> 0.02433767 | HY7: =HX7 -> 0.02433767 | HZ7: =HY7 -> 0.02433767 | IA7: =HZ7 -> 0.02433767 | IB7: =IA7 -> 0.02433767 | IC7: =IB7 -> 0.02433767 | ID7: =IC7 -> 0.02433767 | IE7: =ID7 -> 0.02433767 | ... IH7: =IG7 -> 0.02433767 | II7: 0.025 | IJ7: =II7 -> 0.025 | IK7: =IJ7 -> 0.025 | IL7: =IK7 -> 0.025 | IM7: =IL7 -> 0.025 | IN7: =IM7 -> 0.025 | IO7: =IN7 -> 0.025 | IP7: =IO7 -> 0.025 | IQ7: =IP7 -> 0.025 | ... IT7: =IS7 -> 0.025 | IU7: =II7 -> 0.025 | IV7: =IU7 -> 0.025 | IW7: =IV7 -> 0.025 | IX7: =IW7 -> 0.025 | IY7: =IX7 -> 0.025 | IZ7: =IY7 -> 0.025 | JA7: =IZ7 -> 0.025 | JB7: =JA7 -> 0.025 | JC7: =JB7 -> 0.025 | ... JF7: =JE7 -> 0.025 | JG7: 0 | JH7: =JG7 -> 0 | JI7: =JH7 -> 0 | JJ7: =JI7 -> 0 | JK7: =JJ7 -> 0 | JL7: =JK7 -> 0 | JM7: =JL7 -> 0 | JN7: =JM7 -> 0 | JO7: =JN7 -> 0 | ... JR7: =JQ7 -> 0 | JS7: 0 | JT7: =JS7 -> 0 | JU7: =JT7 -> 0 | JV7: =JU7 -> 0 | JW7: =JV7 -> 0 | JX7: =JW7 -> 0 | JY7: =JX7 -> 0 | JZ7: =JY7 -> 0 | KA7: =JZ7 -> 0 | ... KD7: =KC7 -> 0
